Workbook
Name _CDR2: #REF!
Name _fcf10: #REF!
Name _fcf5: #REF!
Name \c: #REF!
Name \p: #REF!
Name \s: #REF!
Name \z: #REF!
Name a_oc_limit: #REF!
Name aaa: OFFSET(#REF!,MATCH(def_prog,#REF!,0),MATCH(LIBOR_shock,#REF!,0))
Name aaa: OFFSET(#REF!,MATCH(def_prog,#REF!,0),MATCH(LIBOR_shock,#REF!,0))
Name aasdfsadfadg: #REF!
Name AGG_PRISTINE: #REF!
Name AM_Base_Speed: #REF!
Name AM_BBG_Collat_Type: #REF!
Name AM_BBG_Name: #REF!
Name AM_BBG_Rating: #REF!
Name AM_closeDate: #REF!
Name AM_Coupon_Frequency: #REF!
Name AM_Curr_Prin_Bal: #REF!
Name AM_Cusip: #REF!
Name AM_Factor: #REF!
Name AM_Fast_Scaler: #REF!
Name AM_Floater: #REF!
Name AM_In_BBG: #REF!
Name AM_In_Intex: #REF!
Name AM_InventoryName: #REF!
Name AM_Orig_Prin_Bal: #REF!
Name AM_Override: #REF!
Name AM_Pricing_Speed: #REF!
Name AM_Pricing_Speed_Unit: #REF!
Name AM_Rating_Agency: #REF!
Name AM_Refresh: #REF!
Name Am_Sked: #REF!
Name AM_Slow_Scaler: #REF!
Name AM_Speed_1M: #REF!
Name AM_Speed_1M_Unit: #REF!
Name AM_Speed_3M: #REF!
Name AM_Speed_3M_Unit: #REF!
Name AM_Speed_6M: #REF!
Name AM_Speed_6M_Unit: #REF!
Name AM_Speed_Unit: #REF!
Name AM_WH_Position: #REF!
Name AM_WH_Position_User: #REF!
Name Am.running: #REF!
Name amort: #REF!
Name Anchor_T1: #REF!
Name Anchor_T2: #REF!
Name Anchor_T3: #REF!
Name Annual: #REF!
Name as: #REF!
Name Asset_Swap_Toggle: #REF!
Name AverageLife: #REF!
Name AveragePar: #REF!
Name Avg_Life: #REF!
Name AvgIssuerParCurrent: #REF!
Name Balance_Sheet: #REF!
Name BaseYear: #REF!
Name bbbb: #REF!
Name BE_Output_Area: #REF!
Name BE_Table_Ref: #REF!

Sheet INSTRUCTIONS
A1: SUMMARY NOTES ON USING THE MODEL
A3: The goal of any good model is to develop a financial framework to understand the operations of a business, to create questions that otherwise wouldn’t have been apparent, and to ultimately develop a buy/sell opinion based on comparable companies and industries. A model without a comparison set is a study of one, and its difficult to draw conclusions based on a study of one. In addition to creating a model to form an opinion, I have found the list of questions that Ryan developed a number of years ago at Pacholder to be very helpful in understanding the economic and operational value of a business. Click on the link, print it out and keep it handy while you are filling in the data. It will help you keep perspective on your goal.
A5: S:\Target Companies\Langdon Company Questions.xls
A7: The most recent 10-K is usually the best place to begin when starting a model because it has a description of the company's most recent operations, its business risks and its last three years of financial statements. You can start at the beginning and read thru the filing, or go straight to the financial statements, populate the model and then return to read about the operations and risks.
A9: Now for the model….
A11: One note before we begin. IF YOU CHANGE THIS TEMPLATE WITHOUT TALKING TO ONE OF US OR USE THE ORIGINAL INSTEAD OF SAVING A COPY, PACK YOUR DESK UP AND DON’T BOTHER SAYING GOODBYE.
A13: STEP 1
B14: Save as the template model to the company's folder on the S drive.
A16: STEP 2
B17: A. Go to the SUMMARY tab and enter the company name at the top. Don’t do anything else on this tab; we will come back to it later.
A19: STEP 3
B20: A. Go to the MODEL tab
B21: B. It is better to input the historical numbers and then go back and fill in the estimates once you understand the business.
B22: C. At the top of the page is the business segment section. This is usually in the notes or MD&A section of a company's financials. You can either input the numbers here, or if the company gives you more data like segment costs and capex, you can input them on the segment breakdown tab. I would ignore this section and come back to it when you get to those sections in the financials.
B23: D. Start at the INCOME STATEMENT section
C24: 1. All inputs in the model will be blue. This is true for historical numbers and for the inputs that drive estimates. Also, the lables on the left hand side of the model will be blue to let you know where you should be putting data in. For example, total revenue and cost of goods are a blue font because that is something that you need to input. Gross profit is not because it is a formula.
C25: 2. REMEMBER, this section is supposed to mirror the financial statements. Feel free to add and take away as need be.
C26: 3. Make sure when you are done with this section that net income on the model and net income in the financial statements match.
B27: E. Next go to the CASH FLOW STATEMENT section
C28: 1. This section is a little harder because the goal is to have the change in cash be the same between the model and the financial statements. However, instead of starting at net income, you will be starting with revenue. This will make you ask questions about how cash is actually created at the company and hopefully will raise red flags (ex/ Worldcom) if they are not. Always keep your eye out for how the company accounts for different things like revenue and costs and how cash actually flows thru the statements.
C29: 2. The first section is trying to create an accurate EBITDA. Most of this section should be formulas linking to the income statement section. Usually the only input is depreciation and amortization. However, be sure to add line items above EBITDA, so that all non-recurring, non-cash items are added back to create an accurate number. Most of these one times will either be found above SG&A on the income side of costs or will be in the operating cash flow section on the financial statements. An example would be restructuring costs or severance costs that have been included in SG&A. Alot of times companies provide a calculation of EBITDA taking out these costs. Just make sure you agree with all the add-backs. Feel free to add lines underneath if it makes sense to create additional types of EBITDA, like Adjusted EBITDA or EBITDAR.
C30: 3. The Other Expenses (Income) line is where all items from the income statement that weren't added back to create ebitda should now be added back. Everytime you create a new model, some of the formulas in here will change. This line, along with Other Items Impacting Cash, will be the ones causing you the most problems. All expenses are ADDED, and all revenues are SUBTRACTED because this line ties in as a negative in Pretax cash flow.
C31: 4. Changes in Working Capital is the summation of all the items found at the bottom of the cash flow from operations section. Typical line items are change in accounts receivable, change in accounts payable, and change in accrued expenses. Either add all the items together in one cell or use the drop down function on the left hand side to expand the hidden rows and do each line seperately. In the beginning, it might be helpful to do each line seperately so that if you make a mistake, it is easier to find the problem.
C32: 5. Other Items Impacting Cash should be the summation of all other items in cash flow from operations that haven't been added back yet. Once again, you can either put them in one cell or use the hidden lines below.
C33: 6. Make sure that cash flow from operations on the model matches the number on the financial statements before you move on.
C34: 7. All rows below cash flow from continuing ops. should be a replica of the financial statements. When all the lines are summed, change in cash on the model should equal the cash and cash equivalents row on the model and the change in cash in the financial statements.
B35: F. Next open up the hidden rows between the cash flow statement and the balance sheet by clicking on the plus sign on the left hand margin of the model.
C36: 1. This section helps manage the change in the revolver based on debt and cash levels. If cash goes below zero, the company will need to borrow cash. If the company has excess cash, they will probably pay down bank debt. Both these situations should be covered by this section.
C37: 2. The minimun cash assumption line is there to create a minimum amount of cash that the company is willing to hold when it considers how much of the revolver to pay down. Take the size of the debt, revenues, and historical cash balance to estimate the appropriate number.
B38: G. Next go to the BALANCE SHEET SECTION
C39: 1. This should look identical to the company's balance sheet. Fill in the data and make sure it balances at the bottom (row 203). This will be easy for historical numbers, more difficult when trying to create estimates. Row 203 will tell you if your estimates have tied in everything from all 3 sections of the financial statements. If the balance isnt zero, then something isnt being factored into creating future assets and liabilities.
B40: H. Lastly is the METRICS section.
C41: 1. The bottom section is for metrics that can be used to drive estimates. These metrics can be here or on the Segment Breakdown tab, whichever is more helpful. If you change anything in the selected ratios section and your balance sheet doesn’t change on both the asset and liability side, then you need to recheck your formulas for errors.
A42: STEP 4
B43: Go to SEGMENT BREAKDOWN TAB
C44: 1. If the company gives you the data, break up revenues and profitability by the operating units. This helps show if there is a good company/bad company situation and will make driving estimates easier and more accurate. An example would be a company that makes windows and siding and tells you information about both segments.
C45: 2. The model is originally designed to tie in this section with the Model tab. Put in the names of the segments at the top and it will change the segment names on the model tab and each section below this one.
A47: STEP 5
B48: Go to the NOTES tab
C49: 1. As you are reading the financial statements, talking to analysts, talking to the company, be sure to record important data on this tab. Include the date and the person.
...

Sheet Summary Pg
B1: Name of Company | O1: ussw5 curncy | P1: US0003M Index
B2: Summary Page | L2: TODAY: | M2: =TODAY() -> 46083 | O2: FEDL01 Index
L3: LIBOR: | M3: =+_xll.BDP(P1,O4)/100 -> #NAME?
B4: ="Public Company: "&$O$5 -> Public Company: | L4: 5yr swap: | M4: =_xll.BDP(O1,O4)/100 -> #NAME? | O4: PX LAST
B5: Current Shareholders | L5: FED FUNDS: | M5: =_xll.BDP(O2,O4)/100 -> #NAME?
D7: Amount | G7: Market | I7: Market | J7: LTM EBITDA | K7: =+L51 -> 0 | L7: =+TEXT(M29, "YY")&" EBITDA" -> 15 EBITDA | M7: =+M51 -> 0
B8: ($ in millions) | D8: 42277 | E8: Coupon | F8: Maturity | G8: Price | H8: Yield | I8: Value | J8: Book | K8: Market | L8: Book | M8: Market
B10: Revolver | H10: =+YIELD($M$2,F10,$M$3+E10/10000,G10,100,4) -> #NAME? | I10: =IF(OR(G10=0,ISERR((D10*G10)/100)),D10,(D10*G10)/100) -> 0
B11: Term Loan B | H11: =+YIELD($M$2,F11,$M$3+E11/10000,G11,100,4) -> #NAME? | I11: =IF(OR(G11=0,ISERR((D11*G11)/100)),D11,(D11*G11)/100) -> 0
B12: Other Debt | I12: =IF(OR(G12=0,ISERR((D12*G12)/100)),D12,(D12*G12)/100) -> 0
B13: Total Bank Debt | D13: =SUM(D10:D12) -> 0 | I13: =SUM(I10:I12) -> 0 | J13: =(+D13)/$K$7 -> #DIV/0! | K13: =+I13/$K$7 -> #DIV/0! | L13: =(+D13)/$M$7 -> #DIV/0! | M13: =+I13/$M$7 -> #DIV/0!
B15: Senior Notes | H15: =+YIELD($M$2,F15,E15,G15,100,2) -> #NUM! | I15: =IF(OR(G15=0,ISERR((D15*G15)/100)),D15,(D15*G15)/100) -> 0
B16: Total Senior Debt | D16: =+SUM(D15) -> 0 | I16: =SUM(I15) -> 0 | J16: =+D18/K7 -> #DIV/0! | K16: =+(D13+I16)/K7 -> #DIV/0! | L16: =+D18/M7 -> #DIV/0! | M16: =+(D13+I16)/M7 -> #DIV/0!
B18: Total Debt | D18: =+D16+D13 -> 0 | J18: =(+D18)/$K$7 -> #DIV/0! | L18: =(+D18)/$M$7 -> #DIV/0!
B19: Net Debt | D19: =+D18-D22 -> 0 | J19: =(+D19)/$K$7 -> #DIV/0! | L19: =(+D19)/$M$7 -> #DIV/0!
B21: ="Liquidity ("&TEXT(D8,"mm/dd/yy)") -> Liquidity (09/30/15) | F21: Debt Amortization | I21: Equity Data | L21: TEV / EBITDA
B22: Cash | D22: =+H76 -> 0 | F22: 2014 | I22: Fully Diluted Shares
B23: Available Credit Lines | F23: =+F22+1 -> 2015 | I23: Share Price | K23: =+_xll.BDP($O5&" Equity",O$4) -> #NAME? | L23: LTM | M23: =+$K$26/L51 -> #NAME?
B24: Less: Est. Borrowings | D24: =+D10 -> 0 | F24: =+F23+1 -> 2016 | I24: Total Equity Value | K24: =+K23*K22 -> #NAME? | L24: FYA '13 | M24: =+K26/K51 -> #NAME?
B25: Less: LCs | D25: 0 | F25: =+F24+1 -> 2017 | I25: Net Debt | K25: =+D19 -> 0 | L25: FYA '14 | M25: =+(K24+M79)/M51 -> #NAME?
B26: Excess (Deficit) | D26: =SUM(D22:D25) -> 0 | F26: Thereafter | I26: Total Enterprise Value | K26: =SUM(K24:K25) -> #NAME?
B28: Operating Results | D28: 3 | E28: =+IF(D28=4,1,D28+1) -> 4 | F28: =+IF(E28=4,1,E28+1) -> 1 | G28: =+IF(F28=4,1,F28+1) -> 2 | H28: =+IF(G28=4,1,G28+1) -> 3 | I28: FYA | J28: FYA | K28: FYA | L28: LTM | M28: FYE
D29: =EOMONTH(E29,-3) -> 41912 | E29: =EOMONTH(F29,-3) -> 42004 | F29: =EOMONTH(G29,-3) -> 42094 | G29: =EOMONTH(H29,-3) -> 42185 | H29: =+D8 -> 42277 | I29: 41274 | J29: =+EOMONTH(I29,12) -> 41639 | K29: =+EOMONTH(J29,12) -> 42004 | L29: =+H29 -> 42277 | M29: =+EOMONTH(K29,12) -> 42369
D30: =(TEXT(D29,"yy "))&"Q"&D28 -> 14 Q3 | E30: =(TEXT(E29,"yy "))&"Q"&E28 -> 14 Q4 | F30: =(TEXT(F29,"yy "))&"Q"&F28 -> 15 Q1 | G30: =(TEXT(G29,"yy "))&"Q"&G28 -> 15 Q2 | H30: =(TEXT(H29,"yy "))&"Q"&H28 -> 15 Q3 | I30: =+I29 -> 41274 | J30: =+J29 -> 41639 | K30: =+K29 -> 42004 | L30: =+L29 -> 42277 | M30: =+M29 -> 42369
B31: =+Model!B44 -> Segment 1 | D31: =+HLOOKUP(D$30,Model!$E$7:$BW$223,Model!$A44)/1000 -> 0 | E31: =+HLOOKUP(E$30,Model!$E$7:$BW$223,Model!$A44)/1000 -> 0 | F31: =+HLOOKUP(F$30,Model!$E$7:$BW$223,Model!$A44)/1000 -> 0 | G31: =+HLOOKUP(G$30,Model!$E$7:$BW$223,Model!$A44)/1000 -> 0 | H31: =+HLOOKUP(H$30,Model!$E$7:$BW$223,Model!$A44)/1000 -> 0 | I31: =+HLOOKUP(I$30,Model!$E$7:$BW$223,Model!$A44)/1000 -> 0 | J31: =+HLOOKUP(J$30,Model!$E$7:$BW$223,Model!$A44)/1000 -> 0 | K31: =+HLOOKUP(K$30,Model!$E$7:$BW$223,Model!$A44)/1000 -> 0 | L31: =+SUM(E31:H31) -> 0 | M31: =+HLOOKUP(M$30,Model!$E$7:$BW$223,Model!$A44)/1000 -> 0
B32: % growth yoy | D32: =+HLOOKUP(D$30,Model!$E$7:$BW$223,Model!$A45) -> #DIV/0! | E32: =+HLOOKUP(E$30,Model!$E$7:$BW$223,Model!$A45) -> #DIV/0! | F32: =+HLOOKUP(F$30,Model!$E$7:$BW$223,Model!$A45) -> #DIV/0! | G32: =+HLOOKUP(G$30,Model!$E$7:$BW$223,Model!$A45) -> #DIV/0! | H32: =+HLOOKUP(H$30,Model!$E$7:$BW$223,Model!$A45) -> #DIV/0! | I32: =+HLOOKUP(I$30,Model!$E$7:$BW$223,Model!$A45) -> #DIV/0! | J32: =+HLOOKUP(J$30,Model!$E$7:$BW$223,Model!$A45) -> #DIV/0! | K32: =+HLOOKUP(K$30,Model!$E$7:$BW$223,Model!$A45) -> #DIV/0! | M32: =+HLOOKUP(M$30,Model!$E$7:$BW$223,Model!$A45) -> #DIV/0!
B33: =+Model!B47 -> Segment 2 | D33: =+HLOOKUP(D$30,Model!$E$7:$BW$223,Model!$A47)/1000 -> 0 | E33: =+HLOOKUP(E$30,Model!$E$7:$BW$223,Model!$A47)/1000 -> 0 | F33: =+HLOOKUP(F$30,Model!$E$7:$BW$223,Model!$A47)/1000 -> 0 | G33: =+HLOOKUP(G$30,Model!$E$7:$BW$223,Model!$A47)/1000 -> 0 | H33: =+HLOOKUP(H$30,Model!$E$7:$BW$223,Model!$A47)/1000 -> 0 | I33: =+HLOOKUP(I$30,Model!$E$7:$BW$223,Model!$A47)/1000 -> 0 | J33: =+HLOOKUP(J$30,Model!$E$7:$BW$223,Model!$A47)/1000 -> 0 | K33: =+HLOOKUP(K$30,Model!$E$7:$BW$223,Model!$A47)/1000 -> 0 | L33: =+SUM(E33:H33) -> 0 | M33: =+HLOOKUP(M$30,Model!$E$7:$BW$223,Model!$A47)/1000 -> 0
B34: % growth yoy | D34: =+HLOOKUP(D$30,Model!$E$7:$BW$223,Model!$A48) -> #DIV/0! | E34: =+HLOOKUP(E$30,Model!$E$7:$BW$223,Model!$A48) -> #DIV/0! | F34: =+HLOOKUP(F$30,Model!$E$7:$BW$223,Model!$A48) -> #DIV/0! | G34: =+HLOOKUP(G$30,Model!$E$7:$BW$223,Model!$A48) -> #DIV/0! | H34: =+HLOOKUP(H$30,Model!$E$7:$BW$223,Model!$A48) -> #DIV/0! | I34: =+HLOOKUP(I$30,Model!$E$7:$BW$223,Model!$A48) -> #DIV/0! | J34: =+HLOOKUP(J$30,Model!$E$7:$BW$223,Model!$A48) -> #DIV/0! | K34: =+HLOOKUP(K$30,Model!$E$7:$BW$223,Model!$A48) -> #DIV/0! | M34: =+HLOOKUP(M$30,Model!$E$7:$BW$223,Model!$A48) -> #DIV/0!
B35: =+Model!B50 -> Segment 3 | D35: =+HLOOKUP(D$30,Model!$E$7:$BW$223,Model!$A50)/1000 -> 0 | E35: =+HLOOKUP(E$30,Model!$E$7:$BW$223,Model!$A50)/1000 -> 0 | F35: =+HLOOKUP(F$30,Model!$E$7:$BW$223,Model!$A50)/1000 -> 0 | G35: =+HLOOKUP(G$30,Model!$E$7:$BW$223,Model!$A50)/1000 -> 0 | H35: =+HLOOKUP(H$30,Model!$E$7:$BW$223,Model!$A50)/1000 -> 0 | I35: =+HLOOKUP(I$30,Model!$E$7:$BW$223,Model!$A50)/1000 -> 0 | J35: =+HLOOKUP(J$30,Model!$E$7:$BW$223,Model!$A50)/1000 -> 0 | K35: =+HLOOKUP(K$30,Model!$E$7:$BW$223,Model!$A50)/1000 -> 0 | L35: =+SUM(E35:H35) -> 0 | M35: =+HLOOKUP(M$30,Model!$E$7:$BW$223,Model!$A50)/1000 -> 0
B36: % growth yoy | D36: =+HLOOKUP(D$30,Model!$E$7:$BW$223,Model!$A51) -> #DIV/0! | E36: =+HLOOKUP(E$30,Model!$E$7:$BW$223,Model!$A51) -> #DIV/0! | F36: =+HLOOKUP(F$30,Model!$E$7:$BW$223,Model!$A51) -> #DIV/0! | G36: =+HLOOKUP(G$30,Model!$E$7:$BW$223,Model!$A51) -> #DIV/0! | H36: =+HLOOKUP(H$30,Model!$E$7:$BW$223,Model!$A51) -> #DIV/0! | I36: =+HLOOKUP(I$30,Model!$E$7:$BW$223,Model!$A51) -> #DIV/0! | J36: =+HLOOKUP(J$30,Model!$E$7:$BW$223,Model!$A51) -> #DIV/0! | K36: =+HLOOKUP(K$30,Model!$E$7:$BW$223,Model!$A51) -> #DIV/0! | M36: =+HLOOKUP(M$30,Model!$E$7:$BW$223,Model!$A51) -> #DIV/0!
B37: =+Model!B53 -> Segment 4 | D37: =+HLOOKUP(D$30,Model!$E$7:$BW$223,Model!$A53)/1000 -> 0 | E37: 0 | F37: 0 | G37: 0 | H37: 0 | I37: 0 | J37: 0 | K37: 0 | L37: =+SUM(E37:H37) -> 0 | M37: 0
B38: % growth yoy | D38: =+HLOOKUP(D$30,Model!$E$7:$BW$223,Model!$A54) -> #DIV/0! | E38: =+HLOOKUP(E$30,Model!$E$7:$BW$223,Model!$A54) -> #DIV/0! | F38: =+HLOOKUP(F$30,Model!$E$7:$BW$223,Model!$A54) -> #DIV/0! | G38: =+HLOOKUP(G$30,Model!$E$7:$BW$223,Model!$A54) -> #DIV/0! | H38: =+HLOOKUP(H$30,Model!$E$7:$BW$223,Model!$A54) -> #DIV/0! | I38: =+HLOOKUP(I$30,Model!$E$7:$BW$223,Model!$A54) -> #DIV/0! | J38: =+HLOOKUP(J$30,Model!$E$7:$BW$223,Model!$A54) -> #DIV/0! | K38: =+HLOOKUP(K$30,Model!$E$7:$BW$223,Model!$A54) -> #DIV/0! | M38: =+HLOOKUP(M$30,Model!$E$7:$BW$223,Model!$A54) -> #DIV/0!
B39: =+Model!B56 -> Segment 5 | D39: =+HLOOKUP(D$30,Model!$E$7:$BW$223,Model!$A56)/1000 -> 0 | E39: =+HLOOKUP(E$30,Model!$E$7:$BW$223,Model!$A56)/1000 -> 0 | F39: =+HLOOKUP(F$30,Model!$E$7:$BW$223,Model!$A56)/1000 -> 0 | G39: =+HLOOKUP(G$30,Model!$E$7:$BW$223,Model!$A56)/1000 -> 0 | H39: =+HLOOKUP(H$30,Model!$E$7:$BW$223,Model!$A56)/1000 -> 0 | I39: =+HLOOKUP(I$30,Model!$E$7:$BW$223,Model!$A56)/1000 -> 0 | J39: =+HLOOKUP(J$30,Model!$E$7:$BW$223,Model!$A56)/1000 -> 0 | K39: =+HLOOKUP(K$30,Model!$E$7:$BW$223,Model!$A56)/1000 -> 0 | L39: =+SUM(E39:H39) -> 0 | M39: =+HLOOKUP(M$30,Model!$E$7:$BW$223,Model!$A56)/1000 -> 0
B40: % growth yoy | D40: =+HLOOKUP(D$30,Model!$E$7:$BW$223,Model!$A57) -> #DIV/0! | E40: =+HLOOKUP(E$30,Model!$E$7:$BW$223,Model!$A57) -> #DIV/0! | F40: =+HLOOKUP(F$30,Model!$E$7:$BW$223,Model!$A57) -> #DIV/0! | G40: =+HLOOKUP(G$30,Model!$E$7:$BW$223,Model!$A57) -> #DIV/0! | H40: =+HLOOKUP(H$30,Model!$E$7:$BW$223,Model!$A57) -> #DIV/0! | I40: =+HLOOKUP(I$30,Model!$E$7:$BW$223,Model!$A57) -> #DIV/0! | J40: =+HLOOKUP(J$30,Model!$E$7:$BW$223,Model!$A57) -> #DIV/0! | K40: =+HLOOKUP(K$30,Model!$E$7:$BW$223,Model!$A57) -> #DIV/0! | M40: =+HLOOKUP(M$30,Model!$E$7:$BW$223,Model!$A57) -> #DIV/0!
B42: Total Revenues | D42: =+HLOOKUP(D$30,Model!$E$7:$BW$223,Model!$A59)/1000 -> 0 | E42: =+HLOOKUP(E$30,Model!$E$7:$BW$223,Model!$A59)/1000 -> 0 | F42: =+HLOOKUP(F$30,Model!$E$7:$BW$223,Model!$A59)/1000 -> 0 | G42: =+HLOOKUP(G$30,Model!$E$7:$BW$223,Model!$A59)/1000 -> 0 | H42: =+HLOOKUP(H$30,Model!$E$7:$BW$223,Model!$A59)/1000 -> 0 | I42: =+HLOOKUP(I$30,Model!$E$7:$BW$223,Model!$A59)/1000 -> 0 | J42: =+HLOOKUP(J$30,Model!$E$7:$BW$223,Model!$A59)/1000 -> 0 | K42: =+HLOOKUP(K$30,Model!$E$7:$BW$223,Model!$A59)/1000 -> 0 | L42: =+SUM(E42:H42) -> 0 | M42: =+HLOOKUP(M$30,Model!$E$7:$BW$223,Model!$A59)/1000 -> 0
B43: % growth yoy | D43: =+HLOOKUP(D$30,Model!$E$7:$BW$223,Model!$A60) -> #DIV/0! | E43: =+HLOOKUP(E$30,Model!$E$7:$BW$223,Model!$A60) -> #DIV/0! | F43: =+HLOOKUP(F$30,Model!$E$7:$BW$223,Model!$A60) -> #DIV/0! | G43: =+HLOOKUP(G$30,Model!$E$7:$BW$223,Model!$A60) -> #DIV/0! | H43: =+HLOOKUP(H$30,Model!$E$7:$BW$223,Model!$A60) -> #DIV/0! | I43: =+HLOOKUP(I$30,Model!$E$7:$BW$223,Model!$A60) -> #DIV/0! | J43: =+HLOOKUP(J$30,Model!$E$7:$BW$223,Model!$A60) -> #DIV/0! | K43: =+HLOOKUP(K$30,Model!$E$7:$BW$223,Model!$A60) -> #DIV/0! | M43: =+HLOOKUP(M$30,Model!$E$7:$BW$223,Model!$A60) -> #DIV/0!
B45: Operating Costs | D45: =+HLOOKUP(D$30,Model!$E$7:$BW$223,Model!$A64)/1000 -> 0 | E45: =+HLOOKUP(E$30,Model!$E$7:$BW$223,Model!$A64)/1000 -> 0 | F45: =+HLOOKUP(F$30,Model!$E$7:$BW$223,Model!$A64)/1000 -> 0 | G45: =+HLOOKUP(G$30,Model!$E$7:$BW$223,Model!$A64)/1000 -> 0 | H45: =+HLOOKUP(H$30,Model!$E$7:$BW$223,Model!$A64)/1000 -> 0 | I45: =+HLOOKUP(I$30,Model!$E$7:$BW$223,Model!$A64)/1000 -> 0 | J45: =+HLOOKUP(J$30,Model!$E$7:$BW$223,Model!$A64)/1000 -> 0 | K45: =+HLOOKUP(K$30,Model!$E$7:$BW$223,Model!$A64)/1000 -> 0 | L45: =+SUM(E45:H45) -> 0 | M45: =+HLOOKUP(M$30,Model!$E$7:$BW$223,Model!$A64)/1000 -> 0
B46: % of Revenues | D46: =+D45/D42 -> #DIV/0! | E46: =+E45/E42 -> #DIV/0! | F46: =+F45/F42 -> #DIV/0! | G46: =+G45/G42 -> #DIV/0! | H46: =+H45/H42 -> #DIV/0! | I46: =+I45/I42 -> #DIV/0! | J46: =+J45/J42 -> #DIV/0! | K46: =+K45/K42 -> #DIV/0! | ... M46: =+M45/M42 -> #DIV/0!
B48: G&A | D48: =+HLOOKUP(D$30,Model!$E$7:$BW$223,Model!$A70)/1000 -> 0 | E48: =+HLOOKUP(E$30,Model!$E$7:$BW$223,Model!$A70)/1000 -> 0 | F48: =+HLOOKUP(F$30,Model!$E$7:$BW$223,Model!$A70)/1000 -> 0 | G48: =+HLOOKUP(G$30,Model!$E$7:$BW$223,Model!$A70)/1000 -> 0 | H48: =+HLOOKUP(H$30,Model!$E$7:$BW$223,Model!$A70)/1000 -> 0 | I48: =+HLOOKUP(I$30,Model!$E$7:$BW$223,Model!$A70)/1000 -> 0 | J48: =+HLOOKUP(J$30,Model!$E$7:$BW$223,Model!$A70)/1000 -> 0 | K48: =+HLOOKUP(K$30,Model!$E$7:$BW$223,Model!$A70)/1000 -> 0 | L48: =+SUM(E48:H48) -> 0 | M48: =+HLOOKUP(M$30,Model!$E$7:$BW$223,Model!$A70)/1000 -> 0
B49: % of Revenues | D49: =+D48/D42 -> #DIV/0! | E49: =+E48/E42 -> #DIV/0! | F49: =+F48/F42 -> #DIV/0! | G49: =+G48/G42 -> #DIV/0! | H49: =+H48/H42 -> #DIV/0! | I49: =+I48/I42 -> #DIV/0! | J49: =+J48/J42 -> #DIV/0! | K49: =+K48/K42 -> #DIV/0! | ... M49: =+M48/M42 -> #DIV/0!
...

Sheet Model
B2: =+'Summary Pg'!B1 -> Name of Company
B3: YE Dec 31st
E5: FYE | F5: FYE | G5: FYE | H5: 1 | I5: 2 | J5: 3 | K5: 4 | L5: FYE | M5: 1 | N5: 2 | O5: 3 | P5: 4 | Q5: FYE | R5: 1 | S5: 2 | T5: 3 | U5: 4 | V5: FYE | W5: 1 | X5: 2 | Y5: 3 | Z5: 4 | AA5: FYE | AB5: 1 | AC5: 2 | AD5: 3 | AE5: 4 | AF5: FYE | AG5: 1 | AH5: 2 | AI5: 3 | AJ5: 4 | AK5: FYE | AL5: 1 | AM5: 2 | AN5: 3 | AO5: 4 | AP5: FYE | AQ5: 1 | AR5: 2 | AS5: 3 | AT5: 4 | AU5: FYE | AV5: 1 | AW5: 2 | AX5: 3 | AY5: 4 | AZ5: FYE | BA5: 1 | BB5: 2 | BC5: 3 | BD5: 4 | BE5: FYE | BF5: 1 | BG5: 2 | BH5: 3 | BI5: 4 | BJ5: FYE | BK5: 1 | BL5: 2 | BM5: 3 | BN5: 4 | BO5: FYE | BP5: 2 | BQ5: 2 | BR5: 2 | BS5: 2 | BT5: FYE
B6: (in mm of $) | E6: 37256 | F6: =EOMONTH(E6,12) -> 37621 | G6: =EOMONTH(F6,12) -> 37986 | H6: =EOMONTH(G6,3) -> 38077 | I6: =EOMONTH(H6,3) -> 38168 | J6: =EOMONTH(I6,3) -> 38260 | K6: =EOMONTH(J6,3) -> 38352 | L6: =EOMONTH(G6,12) -> 38352 | M6: =EOMONTH(L6,3) -> 38442 | N6: =EOMONTH(M6,3) -> 38533 | O6: =EOMONTH(N6,3) -> 38625 | P6: =EOMONTH(O6,3) -> 38717 | Q6: =EOMONTH(L6,12) -> 38717 | R6: =EOMONTH(Q6,3) -> 38807 | S6: =EOMONTH(R6,3) -> 38898 | T6: =EOMONTH(S6,3) -> 38990 | U6: =EOMONTH(T6,3) -> 39082 | V6: =EOMONTH(Q6,12) -> 39082 | W6: =EOMONTH(V6,3) -> 39172 | X6: =EOMONTH(W6,3) -> 39263 | Y6: =EOMONTH(X6,3) -> 39355 | Z6: =EOMONTH(Y6,3) -> 39447 | AA6: =+Z6 -> 39447 | AB6: =EOMONTH(AA6,3) -> 39538 | AC6: =EOMONTH(AB6,3) -> 39629 | AD6: =EOMONTH(AC6,3) -> 39721 | AE6: =EOMONTH(AD6,3) -> 39813 | AF6: =+AE6 -> 39813 | AG6: =EOMONTH(AF6,3) -> 39903 | AH6: =EOMONTH(AG6,3) -> 39994 | AI6: =EOMONTH(AH6,3) -> 40086 | AJ6: =EOMONTH(AI6,3) -> 40178 | AK6: =+AJ6 -> 40178 | AL6: =EOMONTH(AK6,3) -> 40268 | AM6: =EOMONTH(AL6,3) -> 40359 | AN6: =EOMONTH(AM6,3) -> 40451 | AO6: =EOMONTH(AN6,3) -> 40543 | AP6: =+AO6 -> 40543 | AQ6: =EOMONTH(AP6,3) -> 40633 | AR6: =EOMONTH(AQ6,3) -> 40724 | AS6: =EOMONTH(AR6,3) -> 40816 | AT6: =EOMONTH(AS6,3) -> 40908 | AU6: =+AT6 -> 40908 | AV6: =EOMONTH(AU6,3) -> 40999 | AW6: =EOMONTH(AV6,3) -> 41090 | AX6: =EOMONTH(AW6,3) -> 41182 | AY6: =EOMONTH(AX6,3) -> 41274 | AZ6: =+AY6 -> 41274 | BA6: =EOMONTH(AZ6,3) -> 41364 | BB6: =EOMONTH(BA6,3) -> 41455 | BC6: =EOMONTH(BB6,3) -> 41547 | BD6: =EOMONTH(BC6,3) -> 41639 | BE6: =+BD6 -> 41639 | BF6: =EOMONTH(BE6,3) -> 41729 | BG6: =EOMONTH(BF6,3) -> 41820 | BH6: =EOMONTH(BG6,3) -> 41912 | BI6: =EOMONTH(BH6,3) -> 42004 | BJ6: =+BI6 -> 42004 | BK6: =EOMONTH(BJ6,3) -> 42094 | BL6: =EOMONTH(BK6,3) -> 42185 | BM6: =EOMONTH(BL6,3) -> 42277 | BN6: =EOMONTH(BM6,3) -> 42369 | BO6: =+BN6 -> 42369 | BP6: =EOMONTH(BO6,3) -> 42460 | BQ6: =EOMONTH(BP6,3) -> 42551 | BR6: =EOMONTH(BQ6,3) -> 42643 | BS6: =EOMONTH(BR6,3) -> 42735 | BT6: =+BS6 -> 42735
A7: 1 | E7: =+E6 -> 37256 | F7: =+F6 -> 37621 | G7: =+G6 -> 37986 | H7: =(TEXT(H6,"yy "))&"Q"&H5 -> 04 Q1 | I7: =(TEXT(I6,"yy "))&"Q"&I5 -> 04 Q2 | J7: =(TEXT(J6,"yy "))&"Q"&J5 -> 04 Q3 | K7: =(TEXT(K6,"yy "))&"Q"&K5 -> 04 Q4 | L7: =+L6 -> 38352 | M7: =(TEXT(M6,"yy "))&"Q"&M5 -> 05 Q1 | N7: =(TEXT(N6,"yy "))&"Q"&N5 -> 05 Q2 | O7: =(TEXT(O6,"yy "))&"Q"&O5 -> 05 Q3 | P7: =(TEXT(P6,"yy "))&"Q"&P5 -> 05 Q4 | Q7: =+Q6 -> 38717 | R7: =(TEXT(R6,"yy "))&"Q"&R5 -> 06 Q1 | S7: =(TEXT(S6,"yy "))&"Q"&S5 -> 06 Q2 | T7: =(TEXT(T6,"yy "))&"Q"&T5 -> 06 Q3 | U7: =(TEXT(U6,"yy "))&"Q"&U5 -> 06 Q4 | V7: =+V6 -> 39082 | W7: =(TEXT(W6,"yy "))&"Q"&W5 -> 07 Q1 | X7: =(TEXT(X6,"yy "))&"Q"&X5 -> 07 Q2 | Y7: =(TEXT(Y6,"yy "))&"Q"&Y5 -> 07 Q3 | Z7: =(TEXT(Z6,"yy "))&"Q"&Z5 -> 07 Q4 | AA7: =+AA6 -> 39447 | AB7: =(TEXT(AB6,"yy "))&"Q"&AB5 -> 08 Q1 | AC7: =(TEXT(AC6,"yy "))&"Q"&AC5 -> 08 Q2 | AD7: =(TEXT(AD6,"yy "))&"Q"&AD5 -> 08 Q3 | AE7: =(TEXT(AE6,"yy "))&"Q"&AE5 -> 08 Q4 | AF7: =+AF6 -> 39813 | AG7: =(TEXT(AG6,"yy "))&"Q"&AG5 -> 09 Q1 | AH7: =(TEXT(AH6,"yy "))&"Q"&AH5 -> 09 Q2 | AI7: =(TEXT(AI6,"yy "))&"Q"&AI5 -> 09 Q3 | AJ7: =(TEXT(AJ6,"yy "))&"Q"&AJ5 -> 09 Q4 | AK7: =+AK6 -> 40178 | AL7: =(TEXT(AL6,"yy "))&"Q"&AL5 -> 10 Q1 | AM7: =(TEXT(AM6,"yy "))&"Q"&AM5 -> 10 Q2 | AN7: =(TEXT(AN6,"yy "))&"Q"&AN5 -> 10 Q3 | AO7: =(TEXT(AO6,"yy "))&"Q"&AO5 -> 10 Q4 | AP7: =+AP6 -> 40543 | AQ7: =(TEXT(AQ6,"yy "))&"Q"&AQ5 -> 11 Q1 | AR7: =(TEXT(AR6,"yy "))&"Q"&AR5 -> 11 Q2 | AS7: =(TEXT(AS6,"yy "))&"Q"&AS5 -> 11 Q3 | AT7: =(TEXT(AT6,"yy "))&"Q"&AT5 -> 11 Q4 | AU7: =+AU6 -> 40908 | AV7: =(TEXT(AV6,"yy "))&"Q"&AV5 -> 12 Q1 | AW7: =(TEXT(AW6,"yy "))&"Q"&AW5 -> 12 Q2 | AX7: =(TEXT(AX6,"yy "))&"Q"&AX5 -> 12 Q3 | AY7: =(TEXT(AY6,"yy "))&"Q"&AY5 -> 12 Q4 | AZ7: =+AZ6 -> 41274 | BA7: =(TEXT(BA6,"yy "))&"Q"&BA5 -> 13 Q1 | BB7: =(TEXT(BB6,"yy "))&"Q"&BB5 -> 13 Q2 | BC7: =(TEXT(BC6,"yy "))&"Q"&BC5 -> 13 Q3 | BD7: =(TEXT(BD6,"yy "))&"Q"&BD5 -> 13 Q4 | BE7: =+BE6 -> 41639 | BF7: =(TEXT(BF6,"yy "))&"Q"&BF5 -> 14 Q1 | BG7: =(TEXT(BG6,"yy "))&"Q"&BG5 -> 14 Q2 | BH7: =(TEXT(BH6,"yy "))&"Q"&BH5 -> 14 Q3 | BI7: =(TEXT(BI6,"yy "))&"Q"&BI5 -> 14 Q4 | BJ7: =+BJ6 -> 42004 | BK7: =(TEXT(BK6,"yy "))&"Q"&BK5 -> 15 Q1 | BL7: =(TEXT(BL6,"yy "))&"Q"&BL5 -> 15 Q2 | BM7: =(TEXT(BM6,"yy "))&"Q"&BM5 -> 15 Q3 | BN7: =(TEXT(BN6,"yy "))&"Q"&BN5 -> 15 Q4 | BO7: =+BO6 -> 42369 | BP7: =(TEXT(BP6,"yy "))&"Q"&BP5 -> 16 Q2 | BQ7: =(TEXT(BQ6,"yy "))&"Q"&BQ5 -> 16 Q2 | BR7: =(TEXT(BR6,"yy "))&"Q"&BR5 -> 16 Q2 | BS7: =(TEXT(BS6,"yy "))&"Q"&BS5 -> 16 Q2 | BT7: =+BT6 -> 42735
A8: =+A7+1 -> 2 | B8: Total Sales | E8: =E59 -> 0 | F8: =F59 -> 0 | G8: =G59 -> 0 | H8: =H59 -> 0 | I8: =I59 -> 0 | J8: =J59 -> 0 | K8: =K59 -> 0 | L8: =L59 -> 0 | ... BT8: =BT59 -> 0
A9: =+A8+1 -> 3 | B9: % change | F9: =F60 -> #DIV/0! | G9: =G60 -> #DIV/0! | L9: =L60 -> #DIV/0! | M9: =M60 -> #DIV/0! | N9: =N60 -> #DIV/0! | O9: =O60 -> #DIV/0! | P9: =P60 -> #DIV/0! | Q9: =Q60 -> #DIV/0! | R9: =R60 -> #DIV/0! | S9: =S60 -> #DIV/0! | ... BT9: =BT60 -> #DIV/0!
A10: =+A9+1 -> 4
A11: =+A10+1 -> 5 | B11: Gross Profit | E11: =E67 -> 0 | F11: =F67 -> 0 | G11: =G67 -> 0 | H11: =H67 -> 0 | I11: =I67 -> 0 | J11: =J67 -> 0 | K11: =K67 -> 0 | L11: =L67 -> 0 | ... BT11: =BT67 -> 0
A12: =+A11+1 -> 6 | B12: Margin (%) | E12: =E11/E8 -> #DIV/0! | F12: =F11/F8 -> #DIV/0! | G12: =G11/G8 -> #DIV/0! | H12: =H11/H8 -> #DIV/0! | I12: =I11/I8 -> #DIV/0! | J12: =J11/J8 -> #DIV/0! | K12: =K11/K8 -> #DIV/0! | L12: =L11/L8 -> #DIV/0! | ... BT12: =BT11/BT8 -> #DIV/0!
A13: =+A12+1 -> 7
A14: =+A13+1 -> 8 | B14: EBITDA | E14: =E113 -> 0 | F14: =F113 -> 0 | G14: =G113 -> 0 | H14: =H113 -> 0 | I14: =I113 -> 0 | J14: =J113 -> 0 | K14: =K113 -> 0 | L14: =L113 -> 0 | ... O14: =O113 -> 0 | P14: =Q14-M14-N14-O14 -> 0 | Q14: =Q113 -> 0 | R14: =R113 -> 0 | S14: =S113 -> 0 | T14: =T113 -> 0 | U14: =U113 -> 0 | V14: =V113 -> 0 | W14: =W113 -> 0 | X14: =X113 -> 0 | ... BT14: =BT113 -> 0
A15: =+A14+1 -> 9 | B15: Margin (%) | E15: =E14/E8 -> #DIV/0! | F15: =F14/F8 -> #DIV/0! | G15: =G14/G8 -> #DIV/0! | H15: =H14/H8 -> #DIV/0! | I15: =I14/I8 -> #DIV/0! | J15: =J14/J8 -> #DIV/0! | K15: =K14/K8 -> #DIV/0! | L15: =L14/L8 -> #DIV/0! | ... BT15: =BT14/BT8 -> #DIV/0!
A16: =+A15+1 -> 10 | B16: % change | F16: =F14/E14-1 -> #DIV/0! | G16: =G14/F14-1 -> #DIV/0! | L16: =L14/G14-1 -> #DIV/0! | M16: =M14/H14-1 -> #DIV/0! | N16: =N14/I14-1 -> #DIV/0! | O16: =O14/J14-1 -> #DIV/0! | P16: =P14/K14-1 -> #DIV/0! | Q16: =Q14/L14-1 -> #DIV/0! | R16: =R14/M14-1 -> #DIV/0! | S16: =S14/N14-1 -> #DIV/0! | ... BT16: =BT14/BO14-1 -> #DIV/0!
A17: =+A16+1 -> 11
A18: =+A17+1 -> 12 | B18: Cash Interest Expense, net | E18: =-E117+E118 -> 0 | F18: =-F117+F118 -> 0 | G18: =-G117+G118 -> 0 | H18: =-H117+H118 -> 0 | I18: =-I117+I118 -> 0 | J18: =-J117+J118 -> 0 | K18: =-K117+K118 -> 0 | L18: =-L117+L118 -> 0 | ... BT18: =-BT117+BT118 -> 0
A19: =+A18+1 -> 13 | B19: Changes In Working Capital | E19: =E131 -> 0 | F19: =F131 -> 0 | G19: =G131 -> 0 | H19: =H131 -> 0 | I19: =I131 -> 0 | J19: =J131 -> 0 | K19: =K131 -> 0 | L19: =L131 -> 0 | ... BT19: =BT131 -> 0
A20: =+A19+1 -> 14 | B20: =B150 -> Capital Expenditures | E20: =E150 -> 0 | F20: =F150 -> 0 | G20: =G150 -> 0 | H20: =H150 -> 0 | I20: =I150 -> 0 | J20: =J150 -> 0 | K20: =K150 -> 0 | L20: =L150 -> 0 | ... BT20: =BT150 -> #DIV/0!
A21: =+A20+1 -> 15 | B21: Taxes | E21: =+E126 -> 0 | F21: =+F126 -> 0 | G21: =+G126 -> 0 | H21: =+H126 -> 0 | I21: =+I126 -> 0 | J21: =+J126 -> 0 | K21: =+K126 -> 0 | L21: =+L126 -> 0 | ... BT21: =+BT126 -> #DIV/0!
A22: =+A21+1 -> 16 | B22: FCF | E22: =+E14+SUM(E18:E21) -> 0 | F22: =+F14+SUM(F18:F21) -> 0 | G22: =+G14+SUM(G18:G21) -> 0 | H22: =+H14+SUM(H18:H21) -> 0 | I22: =+I14+SUM(I18:I21) -> 0 | J22: =+J14+SUM(J18:J21) -> 0 | K22: =+K14+SUM(K18:K21) -> 0 | L22: =+L14+SUM(L18:L21) -> 0 | ... BT22: =+BT14+SUM(BT18:BT21) -> #DIV/0!
A23: =+A22+1 -> 17 | B23: Margin (%) | E23: =E22/E8 -> #DIV/0! | F23: =F22/F8 -> #DIV/0! | G23: =G22/G8 -> #DIV/0! | H23: =H22/H8 -> #DIV/0! | I23: =I22/I8 -> #DIV/0! | J23: =J22/J8 -> #DIV/0! | K23: =K22/K8 -> #DIV/0! | L23: =L22/L8 -> #DIV/0! | ... BT23: =BT22/BT8 -> #DIV/0!
A24: =+A23+1 -> 18
A25: =+A24+1 -> 19
A26: =+A25+1 -> 20 | B26: Cash Flow From Continuing Oper. | E26: =E147 -> 0 | F26: =F147 -> 0 | G26: =G147 -> 0 | H26: =H147 -> 0 | I26: =I147 -> 0 | J26: =J147 -> 0 | K26: =K147 -> 0 | L26: =L147 -> 0 | ... BT26: =BT147 -> #DIV/0!
A27: =+A26+1 -> 21 | B27: Change In Cash | E27: =E177 -> 0 | F27: =F177 -> 0 | G27: =G177 -> 0 | H27: =H177 -> 0 | I27: =I177 -> 0 | J27: =J177 -> 0 | K27: =K177 -> 0 | L27: =L177 -> 0 | ... BT27: =BT177 -> #DIV/0!
A28: =+A27+1 -> 22 | B28: Net Cash | E28: =E179 -> 0 | F28: =F179 -> 0 | G28: =G179 -> 0 | H28: =H179 -> 0 | I28: =I179 -> 0 | J28: =J179 -> 0 | K28: =K179 -> 0 | L28: =L179 -> 0 | ... BT28: =BT179 -> #DIV/0!
A29: =+A28+1 -> 23
A30: =+A29+1 -> 24 | B30: LTM RATIOS
A31: =+A30+1 -> 25
A32: =+A31+1 -> 26 | B32: Cash Interest Coverage | E32: =E14/-(E18) -> #DIV/0! | F32: =F14/-(F18) -> #DIV/0! | G32: =G14/-(G18) -> #DIV/0! | K32: =(K14+I14+J14+H14)/-(K18+I18+J18+H18) -> #DIV/0! | L32: =L14/-(L18) -> #DIV/0! | M32: =(M14+K14+I14+J14)/-(M18+K18+I18+J18) -> #DIV/0! | N32: =(N14+J14+M14+K14)/-(N18+J18+M18+K18) -> #DIV/0! | O32: =(O14+M14+N14+K14)/-(O18+M18+N18+K18) -> #DIV/0! | P32: =(P14+N14+O14+M14)/-(P18+N18+O18+M18) -> #DIV/0! | Q32: =Q14/-(Q18) -> #DIV/0! | R32: =(R14+P14+N14+O14)/-(R18+P18+N18+O18) -> #DIV/0! | S32: =(S14+O14+R14+P14)/-(S18+O18+R18+P18) -> #DIV/0! | T32: =(T14+R14+S14+P14)/-(T18+R18+S18+P18) -> #DIV/0! | U32: =(U14+S14+T14+R14)/-(U18+S18+T18+R18) -> #DIV/0! | V32: =V14/-(V18) -> #DIV/0! | W32: =(W14+U14+S14+T14)/-(W18+U18+S18+T18) -> #DIV/0! | X32: =(X14+T14+W14+U14)/-(X18+T18+W18+U18) -> #DIV/0! | Y32: =(Y14+W14+X14+U14)/-(Y18+W18+X18+U18) -> #DIV/0! | Z32: =(Z14+X14+Y14+W14)/-(Z18+X18+Y18+W18) -> #DIV/0! | AA32: =AA14/-(AA18) -> #DIV/0! | AB32: =(AB14+Z14+X14+Y14)/-(AB18+Z18+X18+Y18) -> #DIV/0! | AC32: =(AC14+Y14+AB14+Z14)/-(AC18+Y18+AB18+Z18) -> #DIV/0! | AD32: =(AD14+AB14+AC14+Z14)/-(AD18+AB18+AC18+Z18) -> #DIV/0! | AE32: =(AE14+AC14+AD14+AB14)/-(AE18+AC18+AD18+AB18) -> #DIV/0! | AF32: =AF14/-(AF18) -> #DIV/0! | AG32: =(AG14+AE14+AC14+AD14)/-(AG18+AE18+AC18+AD18) -> #DIV/0! | AH32: =(AH14+AD14+AG14+AE14)/-(AH18+AD18+AG18+AE18) -> #DIV/0! | AI32: =(AI14+AG14+AH14+AE14)/-(AI18+AG18+AH18+AE18) -> #DIV/0! | AJ32: =(AJ14+AH14+AI14+AG14)/-(AJ18+AH18+AI18+AG18) -> #DIV/0! | AK32: =AK14/-(AK18) -> #DIV/0! | AL32: =(AL14+AJ14+AH14+AI14)/-(AL18+AJ18+AH18+AI18) -> #DIV/0! | AM32: =(AM14+AI14+AL14+AJ14)/-(AM18+AI18+AL18+AJ18) -> #DIV/0! | AN32: =(AN14+AL14+AM14+AJ14)/-(AN18+AL18+AM18+AJ18) -> #DIV/0! | AO32: =(AO14+AM14+AN14+AL14)/-(AO18+AM18+AN18+AL18) -> #DIV/0! | AP32: =AP14/-(AP18) -> #DIV/0! | AQ32: =(AQ14+AO14+AM14+AN14)/-(AQ18+AO18+AM18+AN18) -> #DIV/0! | AR32: =(AR14+AN14+AQ14+AO14)/-(AR18+AN18+AQ18+AO18) -> #DIV/0! | AS32: =(AS14+AQ14+AR14+AO14)/-(AS18+AQ18+AR18+AO18) -> #DIV/0! | AT32: =(AT14+AR14+AS14+AQ14)/-(AT18+AR18+AS18+AQ18) -> #DIV/0! | AU32: =AU14/-(AU18) -> #DIV/0! | AV32: =(AV14+AT14+AR14+AS14)/-(AV18+AT18+AR18+AS18) -> #DIV/0! | AW32: =(AW14+AS14+AV14+AT14)/-(AW18+AS18+AV18+AT18) -> #DIV/0! | AX32: =(AX14+AV14+AW14+AT14)/-(AX18+AV18+AW18+AT18) -> #DIV/0! | AY32: =(AY14+AW14+AX14+AV14)/-(AY18+AW18+AX18+AV18) -> #DIV/0! | AZ32: =AZ14/-(AZ18) -> #DIV/0! | BA32: =(BA14+AY14+AW14+AX14)/-(BA18+AY18+AW18+AX18) -> #DIV/0! | BB32: =(BB14+AX14+BA14+AY14)/-(BB18+AX18+BA18+AY18) -> #DIV/0! | BC32: =(BC14+BA14+BB14+AY14)/-(BC18+BA18+BB18+AY18) -> #DIV/0! | BD32: =(BD14+BB14+BC14+BA14)/-(BD18+BB18+BC18+BA18) -> #DIV/0! | BE32: =BE14/-(BE18) -> #DIV/0! | BF32: =(BF14+BD14+BB14+BC14)/-(BF18+BD18+BB18+BC18) -> #DIV/0! | BG32: =(BG14+BC14+BF14+BD14)/-(BG18+BC18+BF18+BD18) -> #DIV/0! | BH32: =(BH14+BF14+BG14+BD14)/-(BH18+BF18+BG18+BD18) -> #DIV/0! | BI32: =(BI14+BG14+BH14+BF14)/-(BI18+BG18+BH18+BF18) -> #DIV/0! | BJ32: =BJ14/-(BJ18) -> #DIV/0! | BK32: =(BK14+BI14+BG14+BH14)/-(BK18+BI18+BG18+BH18) -> #DIV/0! | BL32: =(BL14+BH14+BK14+BI14)/-(BL18+BH18+BK18+BI18) -> #DIV/0! | BM32: =(BM14+BI14+BL14+BJ14)/-(BM18+BI18+BL18+BJ18) -> #DIV/0! | BN32: =(BN14+BL14+BM14+BK14)/-(BN18+BL18+BM18+BK18) -> #DIV/0! | BO32: =BO14/-(BO18) -> #DIV/0! | BP32: =(BP14+BN14+BL14+BM14)/-(BP18+BN18+BL18+BM18) -> #DIV/0! | BQ32: =(BQ14+BM14+BP14+BN14)/-(BQ18+BM18+BP18+BN18) -> #DIV/0! | BR32: =(BR14+BP14+BQ14+BN14)/-(BR18+BP18+BQ18+BN18) -> #DIV/0! | BS32: =(BS14+BQ14+BR14+BP14)/-(BS18+BQ18+BR18+BP18) -> #DIV/0! | BT32: =BT14/-(BT18) -> #DIV/0!
A33: =+A32+1 -> 27 | B33: Consolidated Coverage | E33: =E14/E117 -> #DIV/0! | F33: =F14/F117 -> #DIV/0! | G33: =G14/G117 -> #DIV/0! | K33: =(K14+J14+I14+H14)/(K85+J85+I85+H85) -> #DIV/0! | L33: =L14/L117 -> #DIV/0! | M33: =(M14+K14+J14+I14)/(M85+K85+J85+I85) -> #DIV/0! | N33: =(N14+M14+K14+J14)/(N85+M85+K85+J85) -> #DIV/0! | O33: =(O14+N14+M14+K14)/(O85+N85+M85+K85) -> #DIV/0! | P33: =(P14+O14+N14+M14)/(P85+O85+N85+M85) -> #DIV/0! | Q33: =Q14/Q117 -> #DIV/0! | R33: =(R14+P14+O14+N14)/(R85+P85+O85+N85) -> #DIV/0! | S33: =(S14+R14+P14+O14)/(S85+R85+P85+O85) -> #DIV/0! | T33: =(T14+S14+R14+P14)/(T85+S85+R85+P85) -> #DIV/0! | U33: =(U14+T14+S14+R14)/(U85+T85+S85+R85) -> #DIV/0! | V33: =V14/V117 -> #DIV/0! | W33: =(W14+U14+T14+S14)/(W85+U85+T85+S85) -> #DIV/0! | X33: =(X14+W14+U14+T14)/(X85+W85+U85+T85) -> #DIV/0! | Y33: =(Y14+X14+W14+U14)/(Y85+X85+W85+U85) -> #DIV/0! | Z33: =(Z14+Y14+X14+W14)/(Z85+Y85+X85+W85) -> #DIV/0! | AA33: =AA14/AA117 -> #DIV/0! | AB33: =(AB14+Z14+Y14+X14)/(AB85+Z85+Y85+X85) -> #DIV/0! | AC33: =(AC14+AB14+Z14+Y14)/(AC85+AB85+Z85+Y85) -> #DIV/0! | AD33: =(AD14+AC14+AB14+Z14)/(AD85+AC85+AB85+Z85) -> #DIV/0! | AE33: =(AE14+AD14+AC14+AB14)/(AE85+AD85+AC85+AB85) -> #DIV/0! | AF33: =AF14/AF117 -> #DIV/0! | AG33: =(AG14+AE14+AD14+AC14)/(AG85+AE85+AD85+AC85) -> #DIV/0! | AH33: =(AH14+AG14+AE14+AD14)/(AH85+AG85+AE85+AD85) -> #DIV/0! | AI33: =(AI14+AH14+AG14+AE14)/(AI85+AH85+AG85+AE85) -> #DIV/0! | AJ33: =(AJ14+AI14+AH14+AG14)/(AJ85+AI85+AH85+AG85) -> #DIV/0! | AK33: =AK14/AK117 -> #DIV/0! | AL33: =(AL14+AJ14+AI14+AH14)/(AL85+AJ85+AI85+AH85) -> #DIV/0! | AM33: =(AM14+AL14+AJ14+AI14)/(AM85+AL85+AJ85+AI85) -> #DIV/0! | AN33: =(AN14+AM14+AL14+AJ14)/(AN85+AM85+AL85+AJ85) -> #DIV/0! | AO33: =(AO14+AN14+AM14+AL14)/(AO85+AN85+AM85+AL85) -> #DIV/0! | AP33: =AP14/AP117 -> #DIV/0! | AQ33: =(AQ14+AO14+AN14+AM14)/(AQ85+AO85+AN85+AM85) -> #DIV/0! | AR33: =(AR14+AQ14+AO14+AN14)/(AR85+AQ85+AO85+AN85) -> #DIV/0! | AS33: =(AS14+AR14+AQ14+AO14)/(AS85+AR85+AQ85+AO85) -> #DIV/0! | AT33: =(AT14+AS14+AR14+AQ14)/(AT85+AS85+AR85+AQ85) -> #DIV/0! | AU33: =AU14/AU117 -> #DIV/0! | AV33: =(AV14+AT14+AS14+AR14)/(AV85+AT85+AS85+AR85) -> #DIV/0! | AW33: =(AW14+AV14+AT14+AS14)/(AW85+AV85+AT85+AS85) -> #DIV/0! | AX33: =(AX14+AW14+AV14+AT14)/(AX85+AW85+AV85+AT85) -> #DIV/0! | AY33: =(AY14+AX14+AW14+AV14)/(AY85+AX85+AW85+AV85) -> #DIV/0! | AZ33: =AZ14/AZ117 -> #DIV/0! | BA33: =(BA14+AY14+AX14+AW14)/(BA85+AY85+AX85+AW85) -> #DIV/0! | BB33: =(BB14+BA14+AY14+AX14)/(BB85+BA85+AY85+AX85) -> #DIV/0! | BC33: =(BC14+BB14+BA14+AY14)/(BC85+BB85+BA85+AY85) -> #DIV/0! | BD33: =(BD14+BC14+BB14+BA14)/(BD85+BC85+BB85+BA85) -> #DIV/0! | BE33: =BE14/BE117 -> #DIV/0! | BF33: =(BF14+BD14+BC14+BB14)/(BF85+BD85+BC85+BB85) -> #DIV/0! | BG33: =(BG14+BF14+BD14+BC14)/(BG85+BF85+BD85+BC85) -> #DIV/0! | BH33: =(BH14+BG14+BF14+BD14)/(BH85+BG85+BF85+BD85) -> #DIV/0! | BI33: =(BI14+BH14+BG14+BF14)/(BI85+BH85+BG85+BF85) -> #DIV/0! | BJ33: =BJ14/BJ117 -> #DIV/0! | BK33: =(BK14+BI14+BH14+BG14)/(BK85+BI85+BH85+BG85) -> #DIV/0! | BL33: =(BL14+BK14+BI14+BH14)/(BL85+BK85+BI85+BH85) -> #DIV/0! | BM33: =(BM14+BL14+BJ14+BI14)/(BM85+BL85+BJ85+BI85) -> #DIV/0! | BN33: =(BN14+BM14+BL14+BK14)/(BN85+BM85+BL85+BK85) -> #DIV/0! | BO33: =BO14/BO117 -> #DIV/0! | BP33: =(BP14+BN14+BM14+BL14)/(BP85+BN85+BM85+BL85) -> #DIV/0! | BQ33: =(BQ14+BP14+BN14+BM14)/(BQ85+BP85+BN85+BM85) -> #DIV/0! | BR33: =(BR14+BQ14+BP14+BN14)/(BR85+BQ85+BP85+BN85) -> #DIV/0! | BS33: =(BS14+BR14+BQ14+BP14)/(BS85+BR85+BQ85+BP85) -> #DIV/0! | BT33: =BT14/BT117 -> #DIV/0!
A34: =+A33+1 -> 28
A35: =+A34+1 -> 29 | B35: Sec'd Leverage
A36: =+A35+1 -> 30 | B36: Consolidated Leverage
A37: =+A36+1 -> 31
A38: =+A37+1 -> 32
A39: =+A38+1 -> 33 | B39: =B2 -> Name of Company
A40: =+A39+1 -> 34 | B40: Income Statement
A41: =+A40+1 -> 35 | B41: (in mm of $ execept per share amounts) | E41: =+E$5 -> FYE | F41: =+F$5 -> FYE | G41: =+G$5 -> FYE | H41: =+H$5 -> 1 | I41: =+I$5 -> 2 | J41: =+J$5 -> 3 | K41: =+K$5 -> 4 | L41: =+L$5 -> FYE | ... BT41: =+BT$5 -> FYE
A42: =+A41+1 -> 36 | E42: =E6 -> 37256 | F42: =F6 -> 37621 | G42: =G6 -> 37986 | H42: =H6 -> 38077 | I42: =I6 -> 38168 | J42: =J6 -> 38260 | K42: =K6 -> 38352 | L42: =L6 -> 38352 | ... BT42: =BT6 -> 42735
...

Sheet Segment
A1: =+'Summary Pg'!B1 -> Name of Company
A2: Sales- Segment Breakdown
B4: FYE | C4: FYE | D4: FYE | E4: QE | F4: QE | G4: QE | H4: QE | I4: FYE | J4: QE | K4: QE | L4: QE | M4: QE | N4: FYE | O4: QE | P4: QE | Q4: QE | R4: QE | S4: FYE | T4: QE | U4: QE | V4: QE | W4: QE | X4: FYE | Y4: QE | Z4: QE | AA4: QE | AB4: QE | AC4: FYE | AD4: QE | AE4: QE | AF4: QE | AG4: QE | AH4: FYE | AI4: QE | AJ4: QE | AK4: QE | AL4: QE | AM4: FYE | AN4: QE | AO4: QE | AP4: QE | AQ4: QE | AR4: FYE | AS4: QE | AT4: QE | AU4: QE | AV4: QE | AW4: FYE | AX4: QE | AY4: QE | AZ4: QE | BA4: QE | BB4: FYE | BC4: QE | BD4: QE | BE4: QE | BF4: QE | BG4: FYE | BH4: QE | BI4: QE | BJ4: QE | BK4: QE | BL4: FYE | BM4: QE | BN4: QE | BO4: QE | BP4: QE | BQ4: FYE
B5: 37256 | C5: =EOMONTH(B5,12) -> 37621 | D5: =EOMONTH(C5,12) -> 37986 | E5: =EOMONTH(D5,3) -> 38077 | F5: =EOMONTH(E5,3) -> 38168 | G5: =EOMONTH(F5,3) -> 38260 | H5: =EOMONTH(G5,3) -> 38352 | I5: =EOMONTH(D5,12) -> 38352 | J5: =EOMONTH(I5,3) -> 38442 | K5: =EOMONTH(J5,3) -> 38533 | L5: =EOMONTH(K5,3) -> 38625 | M5: =EOMONTH(L5,3) -> 38717 | N5: =EOMONTH(I5,12) -> 38717 | O5: =EOMONTH(N5,3) -> 38807 | P5: =EOMONTH(O5,3) -> 38898 | Q5: =EOMONTH(P5,3) -> 38990 | R5: =EOMONTH(Q5,3) -> 39082 | S5: =EOMONTH(N5,12) -> 39082 | T5: =EOMONTH(S5,3) -> 39172 | U5: =EOMONTH(T5,3) -> 39263 | V5: =EOMONTH(U5,3) -> 39355 | W5: =EOMONTH(V5,3) -> 39447 | X5: =+W5 -> 39447 | Y5: =EOMONTH(X5,3) -> 39538 | Z5: =EOMONTH(Y5,3) -> 39629 | AA5: =EOMONTH(Z5,3) -> 39721 | AB5: =EOMONTH(AA5,3) -> 39813 | AC5: =+AB5 -> 39813 | AD5: =EOMONTH(AC5,3) -> 39903 | AE5: =EOMONTH(AD5,3) -> 39994 | AF5: =EOMONTH(AE5,3) -> 40086 | AG5: =EOMONTH(AF5,3) -> 40178 | AH5: =+AG5 -> 40178 | AI5: =EOMONTH(AH5,3) -> 40268 | AJ5: =EOMONTH(AI5,3) -> 40359 | AK5: =EOMONTH(AJ5,3) -> 40451 | AL5: =EOMONTH(AK5,3) -> 40543 | AM5: =+AL5 -> 40543 | AN5: =EOMONTH(AM5,3) -> 40633 | AO5: =EOMONTH(AN5,3) -> 40724 | AP5: =EOMONTH(AO5,3) -> 40816 | AQ5: =EOMONTH(AP5,3) -> 40908 | AR5: =+AQ5 -> 40908 | AS5: =EOMONTH(AR5,3) -> 40999 | AT5: =EOMONTH(AS5,3) -> 41090 | AU5: =EOMONTH(AT5,3) -> 41182 | AV5: =EOMONTH(AU5,3) -> 41274 | AW5: =+AV5 -> 41274 | AX5: =EOMONTH(AW5,3) -> 41364 | AY5: =EOMONTH(AX5,3) -> 41455 | AZ5: =EOMONTH(AY5,3) -> 41547 | BA5: =EOMONTH(AZ5,3) -> 41639 | BB5: =+BA5 -> 41639 | BC5: =EOMONTH(BB5,3) -> 41729 | BD5: =EOMONTH(BC5,3) -> 41820 | BE5: =EOMONTH(BD5,3) -> 41912 | BF5: =EOMONTH(BE5,3) -> 42004 | BG5: =+BF5 -> 42004 | BH5: =EOMONTH(BG5,3) -> 42094 | BI5: =EOMONTH(BH5,3) -> 42185 | BJ5: =EOMONTH(BI5,3) -> 42277 | BK5: =EOMONTH(BJ5,3) -> 42369 | BL5: =+BK5 -> 42369 | BM5: =EOMONTH(BL5,3) -> 42460 | BN5: =EOMONTH(BM5,3) -> 42551 | BO5: =EOMONTH(BN5,3) -> 42643 | BP5: =EOMONTH(BO5,3) -> 42735 | BQ5: =+BP5 -> 42735

Sheet Debt Detail
B1: US0003M INDEX | C1: PX LAST
B2: =+'Summary Pg'!B1 -> Name of Company
B3: ($ in thousands)
B5: LIBOR | E5: =+_xll.BDH($B$1,$C$1,E8,E8, "days=a", "fill=p")/100 -> #NAME? | F5: =+_xll.BDH($B$1,$C$1,F8,F8, "days=a", "fill=p")/100 -> #NAME? | G5: =+_xll.BDH($B$1,$C$1,G8,G8, "days=a", "fill=p")/100 -> #NAME? | H5: =+_xll.BDH($B$1,$C$1,H8,H8, "days=a", "fill=p")/100 -> #NAME? | I5: =+_xll.BDH($B$1,$C$1,I8,I8, "days=a", "fill=p")/100 -> #NAME? | J5: =+_xll.BDH($B$1,$C$1,J8,J8, "days=a", "fill=p")/100 -> #NAME? | K5: =+_xll.BDH($B$1,$C$1,K8,K8, "days=a", "fill=p")/100 -> #NAME? | L5: =+_xll.BDH($B$1,$C$1,L8,L8, "days=a", "fill=p")/100 -> #NAME? | ... BK5: =+_xll.BDH($B$1,$C$1,BK8,BK8, "days=a", "fill=p")/100 -> #NAME? | BL5: =+_xll.BDP($B$1,$C$1)/100 -> #NAME? | BM5: =+_xll.BDP($B$1,$C$1)/100 -> #NAME? | BN5: =+_xll.BDP($B$1,$C$1)/100 -> #NAME? | BO5: =+_xll.BDP($B$1,$C$1)/100 -> #NAME? | BP5: =+_xll.BDP($B$1,$C$1)/100 -> #NAME? | BQ5: =+_xll.BDP($B$1,$C$1)/100 -> #NAME? | BR5: =+_xll.BDP($B$1,$C$1)/100 -> #NAME? | BS5: =+_xll.BDP($B$1,$C$1)/100 -> #NAME? | BT5: =+_xll.BDP($B$1,$C$1)/100 -> #NAME?
E7: FYA | F7: FYA | G7: FYA | H7: Q1A | I7: Q2A | J7: Q3A | K7: Q4A | L7: FYA | M7: Q1A | N7: Q2A | O7: Q3A | P7: Q4A | Q7: FYA | R7: Q1A | S7: Q2A | T7: Q3A | U7: Q4A | V7: FYA | W7: Q1A | X7: Q2A | Y7: Q3A | Z7: Q4E | AA7: FYE | AB7: Q1E | AC7: Q2E | AD7: Q3E | AE7: Q4E | AF7: FYE | AG7: Q1E | AH7: Q2E | AI7: Q3E | AJ7: Q4E | AK7: FYE | AL7: Q1E | AM7: Q2E | AN7: Q3E | AO7: Q4E | AP7: FYE | AQ7: Q1E | AR7: Q2E | AS7: Q3E | AT7: Q4E | AU7: FYE | AV7: Q1E | AW7: Q2E | AX7: Q3E | AY7: Q4E | AZ7: FYE | BA7: Q1E | BB7: Q2E | BC7: Q3E | BD7: Q4E | BE7: FYE | BF7: Q1E | BG7: Q2E | BH7: Q2E | BI7: Q4E | BJ7: FYE | BK7: Q1E | BL7: Q2E | BM7: Q3E | BN7: Q4E | BO7: FYE | BP7: Q1E | BQ7: Q2E | BR7: Q3E | BS7: Q4E | BT7: FYE
B8: DEBT SCHEDULE: | E8: 37256 | F8: =EOMONTH(E8,12) -> 37621 | G8: =EOMONTH(F8,12) -> 37986 | H8: =EOMONTH(G8,3) -> 38077 | I8: =EOMONTH(H8,3) -> 38168 | J8: =EOMONTH(I8,3) -> 38260 | K8: =EOMONTH(J8,3) -> 38352 | L8: =EOMONTH(G8,12) -> 38352 | M8: =EOMONTH(L8,3) -> 38442 | N8: =EOMONTH(M8,3) -> 38533 | O8: =EOMONTH(N8,3) -> 38625 | P8: =EOMONTH(O8,3) -> 38717 | Q8: =EOMONTH(L8,12) -> 38717 | R8: =EOMONTH(Q8,3) -> 38807 | S8: =EOMONTH(R8,3) -> 38898 | T8: =EOMONTH(S8,3) -> 38990 | U8: =EOMONTH(T8,3) -> 39082 | V8: =EOMONTH(Q8,12) -> 39082 | W8: =EOMONTH(V8,3) -> 39172 | X8: =EOMONTH(W8,3) -> 39263 | Y8: =EOMONTH(X8,3) -> 39355 | Z8: =EOMONTH(Y8,3) -> 39447 | AA8: =+Z8 -> 39447 | AB8: =EOMONTH(AA8,3) -> 39538 | AC8: =EOMONTH(AB8,3) -> 39629 | AD8: =EOMONTH(AC8,3) -> 39721 | AE8: =EOMONTH(AD8,3) -> 39813 | AF8: =+AE8 -> 39813 | AG8: =EOMONTH(AF8,3) -> 39903 | AH8: =EOMONTH(AG8,3) -> 39994 | AI8: =EOMONTH(AH8,3) -> 40086 | AJ8: =EOMONTH(AI8,3) -> 40178 | AK8: =+AJ8 -> 40178 | AL8: =EOMONTH(AK8,3) -> 40268 | AM8: =EOMONTH(AL8,3) -> 40359 | AN8: =EOMONTH(AM8,3) -> 40451 | AO8: =EOMONTH(AN8,3) -> 40543 | AP8: =+AO8 -> 40543 | AQ8: =EOMONTH(AP8,3) -> 40633 | AR8: =EOMONTH(AQ8,3) -> 40724 | AS8: =EOMONTH(AR8,3) -> 40816 | AT8: =EOMONTH(AS8,3) -> 40908 | AU8: =+AT8 -> 40908 | AV8: =EOMONTH(AU8,3) -> 40999 | AW8: =EOMONTH(AV8,3) -> 41090 | AX8: =EOMONTH(AW8,3) -> 41182 | AY8: =EOMONTH(AX8,3) -> 41274 | AZ8: =+AY8 -> 41274 | BA8: =EOMONTH(AZ8,3) -> 41364 | BB8: =EOMONTH(BA8,3) -> 41455 | BC8: =EOMONTH(BB8,3) -> 41547 | BD8: =EOMONTH(BC8,3) -> 41639 | BE8: =+BD8 -> 41639 | BF8: =EOMONTH(BE8,3) -> 41729 | BG8: =EOMONTH(BF8,3) -> 41820 | BH8: =EOMONTH(BG8,3) -> 41912 | BI8: =EOMONTH(BH8,3) -> 42004 | BJ8: =+BI8 -> 42004 | BK8: =EOMONTH(BJ8,3) -> 42094 | BL8: =EOMONTH(BK8,3) -> 42185 | BM8: =EOMONTH(BL8,3) -> 42277 | BN8: =EOMONTH(BM8,3) -> 42369 | BO8: =+BN8 -> 42369 | BP8: =EOMONTH(BO8,3) -> 42460 | BQ8: =EOMONTH(BP8,3) -> 42551 | BR8: =EOMONTH(BQ8,3) -> 42643 | BS8: =EOMONTH(BR8,3) -> 42735 | BT8: =+BS8 -> 42735
A10: 0.05 | B10: Revolving line of credit | AF10: =+AE10 -> 0 | AK10: =+AJ10 -> 0 | AP10: =+AO10 -> 0 | BL10: =BK10-BL19 -> 0 | BM10: =BL10-BM19 -> 0 | BN10: =BM10-BN19 -> 0 | BO10: =+BN10 -> 0 | BP10: =BO10-BP19 -> 0 | BQ10: =BP10-BQ19 -> 0 | BR10: =BQ10-BR19 -> 0 | BS10: =BR10-BS19 -> 0 | BT10: =+BS10 -> 0
A11: 0.05 | B11: Bank loan | AF11: =+AE11 -> 0 | AK11: =+AJ11 -> 0 | AP11: =+AO11 -> 0 | BL11: =BK11-BL20 -> 0 | BM11: =BL11-BM20 -> 0 | BN11: =BM11-BN20 -> 0 | BO11: =+BN11 -> 0 | BP11: =BO11-BP20 -> 0 | BQ11: =BP11-BQ20 -> 0 | BR11: =BQ11-BR20 -> 0 | BS11: =BR11-BS20 -> 0 | BT11: =+BS11 -> 0
A12: 0.05 | B12: Bank loan | AF12: =+AE12 -> 0 | AK12: =+AJ12 -> 0 | AP12: =+AO12 -> 0 | BL12: =BK12-BL21 -> 0 | BM12: =BL12-BM21 -> 0 | BN12: =BM12-BN21 -> 0 | BO12: =+BN12 -> 0 | BP12: =BO12-BP21 -> 0 | BQ12: =BP12-BQ21 -> 0 | BR12: =BQ12-BR21 -> 0 | BS12: =BR12-BS21 -> 0 | BT12: =+BS12 -> 0
A13: 0.07 | B13: Senior notes | AF13: =+AE13 -> 0 | AK13: =+AJ13 -> 0 | AP13: =+AO13 -> 0 | BL13: =BK13-BL22 -> 0 | BM13: =BL13-BM22 -> 0 | BN13: =BM13-BN22 -> 0 | BO13: =+BN13 -> 0 | BP13: =BO13-BP22 -> 0 | BQ13: =BP13-BQ22 -> 0 | BR13: =BQ13-BR22 -> 0 | BS13: =BR13-BS22 -> 0 | BT13: =+BS13 -> 0
A14: 0.07 | B14: Senior notes | AF14: =+AE14 -> 0 | AK14: =+AJ14 -> 0 | AP14: =+AO14 -> 0 | BL14: =BK14-BL23 -> 0 | BM14: =BL14-BM23 -> 0 | BN14: =BM14-BN23 -> 0 | BO14: =+BN14 -> 0 | BP14: =BO14-BP23 -> 0 | BQ14: =BP14-BQ23 -> 0 | BR14: =BQ14-BR23 -> 0 | BS14: =BR14-BS23 -> 0 | BT14: =+BS14 -> 0
A15: 0.08 | B15: Subordinated notes | AF15: =+AE15 -> 0 | AK15: =+AJ15 -> 0 | AP15: =+AO15 -> 0 | BL15: =BK15-BL24 -> 0 | BM15: =BL15-BM24 -> 0 | BN15: =BM15-BN24 -> 0 | BO15: =+BN15 -> 0 | BP15: =BO15-BP24 -> 0 | BQ15: =BP15-BQ24 -> 0 | BR15: =BQ15-BR24 -> 0 | BS15: =BR15-BS24 -> 0 | BT15: =+BS15 -> 0
B16: Total Debt | E16: =SUM(E10:E15) -> 0 | F16: =SUM(F10:F15) -> 0 | G16: =SUM(G10:G15) -> 0 | H16: =SUM(H10:H15) -> 0 | I16: =SUM(I10:I15) -> 0 | J16: =SUM(J10:J15) -> 0 | K16: =SUM(K10:K15) -> 0 | L16: =SUM(L10:L15) -> 0 | ... BT16: =SUM(BT10:BT15) -> 0
B18: Cash maturities:
B19: =B10 -> Revolving line of credit
B20: =B11 -> Bank loan
B21: =B12 -> Bank loan
B22: =B13 -> Senior notes
B23: =B14 -> Senior notes
B24: =B15 -> Subordinated notes
B25: Total | E25: =SUM(E18:E24) -> 0 | F25: =SUM(F18:F24) -> 0 | G25: =SUM(G18:G24) -> 0 | H25: =SUM(H18:H24) -> 0 | I25: =SUM(I18:I24) -> 0 | J25: =SUM(J18:J24) -> 0 | K25: =SUM(K18:K24) -> 0 | L25: =SUM(L18:L24) -> 0 | ... BT25: =SUM(BT18:BT24) -> 0
B27: Cash interest expense:
B28: =B19 -> Revolving line of credit
B29: =B20 -> Bank loan
B30: =B21 -> Bank loan
B31: =B22 -> Senior notes
B32: =B23 -> Senior notes
B33: =B24 -> Subordinated notes
B34: Total | E34: =SUM(E27:E33) -> 0 | F34: =SUM(F27:F33) -> 0 | G34: =SUM(G27:G33) -> 0 | H34: =SUM(H27:H33) -> 0 | I34: =SUM(I27:I33) -> 0 | J34: =SUM(J27:J33) -> 0 | K34: =SUM(K27:K33) -> 0 | L34: =SUM(L27:L33) -> 0 | ... BT34: =SUM(BT27:BT33) -> 0
B36: GAAP interest expense:
B37: =B28 -> Revolving line of credit
B38: =B29 -> Bank loan
B39: =B30 -> Bank loan
B40: =B31 -> Senior notes
B41: =B32 -> Senior notes
B42: =B33 -> Subordinated notes
B43: Total | E43: =SUM(E36:E42) -> 0 | F43: =SUM(F36:F42) -> 0 | G43: =SUM(G36:G42) -> 0 | H43: =SUM(H36:H42) -> 0 | I43: =SUM(I36:I42) -> 0 | J43: =SUM(J36:J42) -> 0 | K43: =SUM(K36:K42) -> 0 | L43: =SUM(L36:L42) -> 0 | ... BT43: =SUM(BT36:BT42) -> 0

Sheet Notes
A1: =+'Summary Pg'!B1 -> Name of Company
A2: Notes
A5: NAME OF PERSON, COMPANY, DATE
A6: Notes of importance include here

Sheet Bullets
A1: =+'Summary Pg'!B1 -> Name of Company
A2: Bullet points

Sheet Mgmt
A1: =+'Summary Pg'!B1 -> Name of Company
A2: Management

Sheet Structure
B1: =+'Summary Pg'!B1 -> Name of Company
B2: Corporate Structure
B7: Sources and Uses | O7: Investor | Q7: Date | R7: $
B8: Transaction | D8: Date | O8: ($MM)
B9: Sources | D9: Uses | H9: Equity Investors | O9: Initial Equity Investment
B10: Term Loans | D10: CEO stock | O10: (+)
B11: Notes | D11: Other stock | H11: Various Parties | L11: 0 | O11: (+)
B12: Equity | D12: Debt | L12: 0 | O12: (-)
B13: Cash | D13: Fees | L13: 0 | O13: (-)
B14: Total | C14: =SUM(C10:C13) -> 0 | D14: Total | E14: =SUM(E10:E13) -> 0 | H14: Total Equity | L14: =SUM(L11:L13) -> 0 | O14: Remaining Equity | R14: =SUM(R9:R13) -> 0
B15: LTM EBITDA | D15: Mult. | E15: =E14/C15 -> #DIV/0!

Sheet Incur Covs
A1: =+'Summary Pg'!B1 -> Name of Company
A2: Covenants
A5: Guarantees
A7: Security
A9: Claw
A11: Restricted Payments
A15: Debt Incurrence
A22: Investments
A24: Mandatory Repayment
A27: Defined Terms
A29: Open Market Purchases

Sheet Main Covs
A1: =+'Summary Pg'!B1 -> Name of Company
A4: BANK DEBT COVENANTS AS OF _________
A6: Consolidated Leverage Ratio | E6: Consolidated Interest Coverage Ratio | I6: Amortization schedule
B8: Current | C8: Actual | F8: Current | G8: Actual | J8: Current | K8: Actual
A10: =+EOMONTH(A9,3) -> 121 | E10: =+EOMONTH(E9,3) -> 121 | I10: =+EOMONTH(I9,3) -> 121
A11: =+EOMONTH(A10,3) -> 213 | E11: =+EOMONTH(E10,3) -> 213 | I11: =+EOMONTH(I10,3) -> 213
A12: =+EOMONTH(A11,3) -> 305 | E12: =+EOMONTH(E11,3) -> 305 | I12: =+EOMONTH(I11,3) -> 305
A13: =+EOMONTH(A12,3) -> 397 | E13: =+EOMONTH(E12,3) -> 397 | I13: =+EOMONTH(I12,3) -> 397
A14: =+EOMONTH(A13,3) -> 486 | E14: =+EOMONTH(E13,3) -> 486 | I14: =+EOMONTH(I13,3) -> 486
A15: =+EOMONTH(A14,3) -> 578 | E15: =+EOMONTH(E14,3) -> 578 | I15: =+EOMONTH(I14,3) -> 578
A16: =+EOMONTH(A15,3) -> 670 | E16: =+EOMONTH(E15,3) -> 670 | I16: =+EOMONTH(I15,3) -> 670
A17: =+EOMONTH(A16,3) -> 762 | E17: =+EOMONTH(E16,3) -> 762 | I17: =+EOMONTH(I16,3) -> 762
A18: =+EOMONTH(A17,3) -> 851 | E18: =+EOMONTH(E17,3) -> 851 | I18: =+EOMONTH(I17,3) -> 851
A19: =+EOMONTH(A18,3) -> 943 | E19: =+EOMONTH(E18,3) -> 943 | I19: =+EOMONTH(I18,3) -> 943
A20: =+EOMONTH(A19,3) -> 1035 | E20: =+EOMONTH(E19,3) -> 1035 | I20: =+EOMONTH(I19,3) -> 1035
A21: =+EOMONTH(A20,3) -> 1127 | E21: =+EOMONTH(E20,3) -> 1127 | I21: =+EOMONTH(I20,3) -> 1127
... A28: =+EOMONTH(A27,3) -> 1766 | E28: =+EOMONTH(E27,3) -> 1766 | I28: =+EOMONTH(I27,3) -> 1766

Sheet DCF
A1: =+'Summary Pg'!B1 -> Name of Company
A2: Discounted Cash Flow Analysis
C5: 2006 | D5: =C5+1 -> 2007 | E5: =D5+1 -> 2008 | F5: =E5+1 -> 2009 | G5: =F5+1 -> 2010 | H5: =G5+1 -> 2011 | I5: =H5+1 -> 2012 | J5: =I5+1 -> 2013 | K5: =J5+1 -> 2014 | ... M5: =L5+1 -> 2016
A6: High Yield Note
A7: Bank Loan
A8: Total LTD | C8: =C7+C6 -> 0
A9: Total Revenue
A10: Rev Growth | D10: =D9/C9-1 -> #DIV/0! | E10: =E9/D9-1 -> #DIV/0! | F10: =F9/E9-1 -> #DIV/0! | G10: =G9/F9-1 -> #DIV/0! | H10: =H9/G9-1 -> #DIV/0! | I10: =I9/H9-1 -> #DIV/0!
A11: EBITDA
A12: EBITDA Margin | C12: =C11/C9 -> #DIV/0! | D12: =D11/D9 -> #DIV/0! | E12: =E11/E9 -> #DIV/0! | F12: =F11/F9 -> #DIV/0! | G12: =G11/G9 -> #DIV/0! | H12: =H11/H9 -> #DIV/0! | I12: =I11/I9 -> #DIV/0!
A13: Interest
A14: Capex
A15: Free Cash Flow | C15: =C11-C13-C14 -> 0 | D15: =D11-D13-D14 -> 0 | E15: =E11-E13-E14 -> 0 | F15: =F11-F13-F14 -> 0 | G15: =G11-G13-G14 -> 0 | H15: =H11-H13-H14 -> 0 | I15: =I11-I13-I14 -> 0 | J15: =J11-J13-J14 -> 0 | ... M15: =M11-M13-M14 -> 0
A17: Coverage | C17: =C11/C13 -> #DIV/0! | D17: =D11/D13 -> #DIV/0! | E17: =E11/E13 -> #DIV/0! | F17: =F11/F13 -> #DIV/0! | G17: =G11/G13 -> #DIV/0! | H17: =H11/H13 -> #DIV/0! | I17: =I11/I13 -> #DIV/0! | J17: =J11/J13 -> #DIV/0! | ... M17: =M11/M13 -> #DIV/0!
A18: Leverage | C18: =C8/C11 -> #DIV/0! | D18: =$D$4/D11 -> #DIV/0! | E18: =$D$4/E11 -> #DIV/0! | F18: =$D$4/F11 -> #DIV/0! | G18: =$D$4/G11 -> #DIV/0! | H18: =$D$4/H11 -> #DIV/0! | I18: =$D$4/I11 -> #DIV/0! | J18: =$D$4/J11 -> #DIV/0! | K18: =$D$4/K11 -> #DIV/0! | ... M18: =$D$4/M11 -> #DIV/0!
A20: NPV
C21: =C5 -> 2006 | D21: =C21+1 -> 2007 | E21: =D21+1 -> 2008 | F21: =E21+1 -> 2009 | G21: =F21+1 -> 2010 | H21: =G21+1 -> 2011 | I21: =H21+1 -> 2012 | J21: =I21+1 -> 2013 | K21: =J21+1 -> 2014 | ... M21: =L21+1 -> 2016
A23: Discount Rate | C23: 0.1
A24: Growth Rate | C24: 0.05
A26: EBITDA | C26: =C11 -> 0 | D26: =D11 -> 0 | E26: =E11 -> 0 | F26: =F11 -> 0 | G26: =G11 -> 0 | H26: =H11 -> 0 | I26: =I11 -> 0 | J26: =J11 -> 0 | ... M26: =M11 -> 0
A27: CAPEX | C27: =C14 -> 0 | D27: =D14 -> 0 | E27: =E14 -> 0 | F27: =F14 -> 0 | G27: =G14 -> 0 | H27: =H14 -> 0 | I27: =I14 -> 0 | J27: =J14 -> 0 | ... M27: =M14 -> 0
A28: Total Unleveraged FCF | C28: =C26-C27 -> 0 | D28: =D26-D27 -> 0 | E28: =E26-E27 -> 0 | F28: =F26-F27 -> 0 | G28: =G26-G27 -> 0 | H28: =H26-H27 -> 0 | I28: =I26-I27 -> 0 | J28: =J26-J27 -> 0 | ... M28: =M26-M27 -> 0
A29: Terminal Value | M29: =(M28*(1+C24))/(C23-C24) -> 0
A30: Total incl. Terminal Value | C30: =C28+C29 -> 0 | D30: =D28+D29 -> 0 | E30: =E28+E29 -> 0 | F30: =F28+F29 -> 0 | G30: =G28+G29 -> 0 | H30: =H28+H29 -> 0 | I30: =I28+I29 -> 0 | J30: =J28+J29 -> 0 | ... M30: =M28+M29 -> 0
A32: NPV | C32: =NPV(C23,C30:M30) -> 0
A33: PS or HoldCo LTD O/S
A34: TEV | C34: =C32-C33-C8 -> 0
A35: F/D CS O/S
A36: NPV per CS | C36: =(C32-C8-C33)/C35 -> #DIV/0!

Sheet SOP
A1: =+'Summary Pg'!B1 -> Name of Company
A2: SUM OF THE PARTS ANALYSIS

Sheet M&A
A1: =+'Summary Pg'!B1 -> Name of Company
A2: COMPANY M&A
A6: Date | B6: Buyer | C6: Seller | D6: Revenue | E6: EBITDA | F6: TEV | G6: Debt | H6: Cash | I6: Stock | J6: Rev Multiple | K6: EBITDA Multiple | L6: Notes
J32: =AVERAGE(J8:J30) -> #DIV/0! | K32: =AVERAGE(K8:K30) -> #DIV/0! | L32: AVERAGE MULTIPLE

Sheet Geographic
A1: =+'Summary Pg'!B1 -> Name of Company
A2: Geographic Breakdown
B4: FYE | C4: FYE | D4: FYE | E4: FYE | F4: FYE | G4: 1 | H4: 2 | I4: 3 | J4: 4 | K4: FYE | L4: 1 | M4: 2 | N4: 3 | O4: 4 | P4: FYE | Q4: 1 | R4: 2 | S4: 3 | T4: 4 | U4: FYE | V4: 1 | W4: 2 | X4: 3 | Y4: 4 | Z4: FYE | AA4: 1 | AB4: 2 | AC4: 3 | AD4: 4 | AE4: FYE | AF4: 1 | AG4: 2 | AH4: 3 | AI4: 4 | AJ4: FYE | AK4: 1 | AL4: 2 | AM4: 3 | AN4: 4 | AO4: FYE | AP4: 1 | AQ4: 2 | AR4: 3 | AS4: 4 | AT4: FYE | AU4: 1 | AV4: 2 | AW4: 3 | AX4: 4 | AY4: FYE | AZ4: 1 | BA4: 2 | BB4: 3 | BC4: 4 | BD4: FYE | BE4: 1 | BF4: 2 | BG4: 3 | BH4: 4 | BI4: FYE | BJ4: 1 | BK4: 2 | BL4: 3 | BM4: 4 | BN4: FYE | BO4: 1 | BP4: 2 | BQ4: 3 | BR4: 4 | BS4: FYE
B5: 36525 | C5: 36891 | D5: 37256 | E5: =EOMONTH(D5,12) -> 37621 | F5: =EOMONTH(E5,12) -> 37986 | G5: =EOMONTH(F5,3) -> 38077 | H5: =EOMONTH(G5,3) -> 38168 | I5: =EOMONTH(H5,3) -> 38260 | J5: =EOMONTH(I5,3) -> 38352 | K5: =EOMONTH(F5,12) -> 38352 | L5: =EOMONTH(K5,3) -> 38442 | M5: =EOMONTH(L5,3) -> 38533 | N5: =EOMONTH(M5,3) -> 38625 | O5: =EOMONTH(N5,3) -> 38717 | P5: =EOMONTH(K5,12) -> 38717 | Q5: =EOMONTH(P5,3) -> 38807 | R5: =EOMONTH(Q5,3) -> 38898 | S5: =EOMONTH(R5,3) -> 38990 | T5: =EOMONTH(S5,3) -> 39082 | U5: =EOMONTH(P5,12) -> 39082 | V5: =EOMONTH(U5,3) -> 39172 | W5: =EOMONTH(V5,3) -> 39263 | X5: =EOMONTH(W5,3) -> 39355 | Y5: =EOMONTH(X5,3) -> 39447 | Z5: =+Y5 -> 39447 | AA5: =EOMONTH(Z5,3) -> 39538 | AB5: =EOMONTH(AA5,3) -> 39629 | AC5: =EOMONTH(AB5,3) -> 39721 | AD5: =EOMONTH(AC5,3) -> 39813 | AE5: =+AD5 -> 39813 | AF5: =EOMONTH(AE5,3) -> 39903 | AG5: =EOMONTH(AF5,3) -> 39994 | AH5: =EOMONTH(AG5,3) -> 40086 | AI5: =EOMONTH(AH5,3) -> 40178 | AJ5: =+AI5 -> 40178 | AK5: =EOMONTH(AJ5,3) -> 40268 | AL5: =EOMONTH(AK5,3) -> 40359 | AM5: =EOMONTH(AL5,3) -> 40451 | AN5: =EOMONTH(AM5,3) -> 40543 | AO5: =+AN5 -> 40543 | AP5: =EOMONTH(AO5,3) -> 40633 | AQ5: =EOMONTH(AP5,3) -> 40724 | AR5: =EOMONTH(AQ5,3) -> 40816 | AS5: =EOMONTH(AR5,3) -> 40908 | AT5: =+AS5 -> 40908 | AU5: =EOMONTH(AT5,3) -> 40999 | AV5: =EOMONTH(AU5,3) -> 41090 | AW5: =EOMONTH(AV5,3) -> 41182 | AX5: =EOMONTH(AW5,3) -> 41274 | AY5: =+AX5 -> 41274 | AZ5: =EOMONTH(AY5,3) -> 41364 | BA5: =EOMONTH(AZ5,3) -> 41455 | BB5: =EOMONTH(BA5,3) -> 41547 | BC5: =EOMONTH(BB5,3) -> 41639 | BD5: =+BC5 -> 41639 | BE5: =EOMONTH(BD5,3) -> 41729 | BF5: =EOMONTH(BE5,3) -> 41820 | BG5: =EOMONTH(BF5,3) -> 41912 | BH5: =EOMONTH(BG5,3) -> 42004 | BI5: =+BH5 -> 42004 | BJ5: =EOMONTH(BI5,3) -> 42094 | BK5: =EOMONTH(BJ5,3) -> 42185 | BL5: =EOMONTH(BK5,3) -> 42277 | BM5: =EOMONTH(BL5,3) -> 42369 | BN5: =+BM5 -> 42369 | BO5: =EOMONTH(BN5,3) -> 42460 | BP5: =EOMONTH(BO5,3) -> 42551 | BQ5: =EOMONTH(BP5,3) -> 42643 | BR5: =EOMONTH(BQ5,3) -> 42735 | BS5: =+BR5 -> 42735
A7: Net Sales
A8: United States
A9: Foreign Countries
A10: Total Sales | B10: =SUM(B8:B9) -> 0 | C10: =SUM(C8:C9) -> 0 | D10: =SUM(D8:D9) -> 0 | E10: =SUM(E8:E9) -> 0 | F10: =SUM(F8:F9) -> 0 | G10: =SUM(G8:G9) -> 0 | H10: =SUM(H8:H9) -> 0 | I10: =SUM(I8:I9) -> 0 | ... Z10: =SUM(Z8:Z9) -> 0 | AE10: =SUM(AE8:AE9) -> 0 | AJ10: =SUM(AJ8:AJ9) -> 0 | AO10: =SUM(AO8:AO9) -> 0 | AT10: =SUM(AT8:AT9) -> 0 | AY10: =SUM(AY8:AY9) -> 0 | BD10: =SUM(BD8:BD9) -> 0 | BI10: =SUM(BI8:BI9) -> 0 | BN10: =SUM(BN8:BN9) -> 0 | BS10: =SUM(BS8:BS9) -> 0

Sheet Customers
A1: =+'Summary Pg'!B1 -> Name of Company
A2: % of Sales by Customer
B4: FYE | C4: FYE | D4: FYE | E4: FYE | F4: FYE | G4: 1 | H4: 2 | I4: 3 | J4: 4 | K4: FYE | L4: 1 | M4: 2 | N4: 3 | O4: 4 | P4: FYE | Q4: 1 | R4: 2 | S4: 3 | T4: 4 | U4: FYE | V4: 1 | W4: 2 | X4: 3 | Y4: 4 | Z4: FYE | AA4: 1 | AB4: 2 | AC4: 3 | AD4: 4 | AE4: FYE | AF4: 1 | AG4: 2 | AH4: 3 | AI4: 4 | AJ4: FYE | AK4: 1 | AL4: 2 | AM4: 3 | AN4: 4 | AO4: FYE | AP4: 1 | AQ4: 2 | AR4: 3 | AS4: 4 | AT4: FYE | AU4: 1 | AV4: 2 | AW4: 3 | AX4: 4 | AY4: FYE | AZ4: 1 | BA4: 2 | BB4: 3 | BC4: 4 | BD4: FYE | BE4: 1 | BF4: 2 | BG4: 3 | BH4: 4 | BI4: FYE | BJ4: 1 | BK4: 2 | BL4: 3 | BM4: 4 | BN4: FYE | BO4: 1 | BP4: 2 | BQ4: 3 | BR4: 4 | BS4: FYE
